<?xml version="1.0"?>
<robot name="orpheus_x4" xmlns:xacro="http://ros.org/wiki/xacro">

	
  <!-- Konstanty robota -->
  <xacro:property name="base_width" value="0.43"/>
  <xacro:property name="base_length" value="0.557"/>
  <xacro:property name="base_height" value="0.119"/>

  <xacro:property name="wheel_radius" value="0.20"/>
  <xacro:property name="wheel_width" value="0.06"/>
  <xacro:property name="wheel_ygap" value="0.042"/>
  <xacro:property name="wheel_zoff" value="0.000"/>
  <xacro:property name="wheel_xoff" value="0.223"/>




<!-- Define intertial property macros  -->

  <xacro:macro name="box_inertia" params="m w h d">
    <inertial>
      <origin xyz="0 0 0" rpy="${pi/2} 0 ${pi/2}"/>
      <mass value="${m}"/>
      <inertia ixx="${(m/12) * (h*h + d*d)}" ixy="0.0" ixz="0.0" iyy="${(m/12) * (w*w + d*d)}" iyz="0.0" izz="${(m/12) * (w*w + h*h)}"/>
    </inertial>
  </xacro:macro>

  <xacro:macro name="cylinder_inertia" params="m r h">
    <inertial>
      <origin xyz="0 0 0" rpy="${pi/2} 0 0" />
      <mass value="${m}"/>
      <inertia ixx="${(m/12) * (3*r*r + h*h)}" ixy = "0" ixz = "0" iyy="${(m/12) * (3*r*r + h*h)}" iyz = "0" izz="${(m/2) * (r*r)}"/>
    </inertial>
  </xacro:macro>


<!-- Telo robota -->

  <link name="base_link">
    <visual>
      <geometry>
        	<!-- <box size="${base_length} ${base_width} ${base_height}"/> -->
        <mesh scale=" 0.001 0.001 0.001" filename="file://$(find robot_models)/meshes/orpheus_x4/Base_orpheus_x4.stl"/> <!-- filename="package://orpheus_x4_description/src/meshes/Base_orpheus_x4.stl" -->
      </geometry>
      <material name="Black">
        <color rgba="0.05 0.05 0.05 1.0"/>
      </material>
    </visual>
    <collision>
      <geometry>
        <box size="${base_length} ${base_width} ${base_height}"/>
      </geometry>
    </collision>

   <xacro:box_inertia m="40" w="${base_width}" d="${base_length}" h="${base_height}"/>
  </link>
  
  
<!-- Stred stopy robota -->
  
  <link name="base_footprint"/>
    <joint name="base_joint" type="fixed">
    	<parent link="base_link"/>
    	<child link="base_footprint"/>
    	<origin xyz="0.0 0.0 ${-(wheel_radius+wheel_zoff)}" rpy="0 0 0"/>
    </joint>
 
<!-- Deska na uchyceni prisluenstvi -->
  
  <link name="mounting_plate_link">
    <visual>
      <geometry>
        <!-- <box size="${base_length} ${base_width} 0.01"/> -->
        <mesh scale=" 0.001 0.001 0.001" filename="file://$(find robot_models)/meshes/orpheus_x4/Mount_plate_orpheus_x4.stl"/>
      </geometry>
      <material name="Silver">
        <color rgba="0.8 0.8 0.8 1"/>
      </material>
    </visual>
    <collision>
      <geometry>
        <box size="${base_length} ${base_width} 0.001"/>
      </geometry>
    </collision>
  <xacro:box_inertia m="1" w="${base_width}" d="${base_length}" h="0.01"/>
  </link> 
  
  <joint name="mounting_plate_joint" type="fixed">
    <parent link="base_link"/>
    <child link="mounting_plate_link"/>
    <origin xyz="0.0 0.0 ${(base_height/2)}" rpy="0 0 0"/>
  </joint>
  
  <!-- Platforma na prislusenstvi -->
  
  <link name="platform_link">
    <visual>
      <geometry>
        <!-- <box size="${base_length} ${base_width} 0.01"/> -->
        <mesh scale=" 0.001 0.001 0.001" filename="file://$(find robot_models)/meshes/orpheus_x4/Orpheus_x4_platform.stl"/>
      </geometry>
      <material name="Silver">
        <color rgba="0.8 0.8 0.8 1"/>
      </material>
    </visual>
    <collision>
      <geometry>
        <box size="0.05 0.08 0.465"/>
      </geometry>
    </collision>
  <xacro:box_inertia m="1" w="${base_width}" d="${base_length}" h="0.01"/>
  </link> 
  
  <joint name="platform_joint" type="fixed">
    <parent link="base_link"/>
    <child link="platform_link"/>
    <origin xyz="${(-base_length/2)-0.020} 0.0 ${(wheel_radius/2 + base_height/2 + 0.018)}" rpy="0 0 0"/>
  </joint>
  
  
<!-- Kola -->
    
  <xacro:macro name="wheel" params="prefix x_reflect y_reflect">
  <link name="${prefix}_link">
      <visual>
        <origin xyz="0 0 0" rpy="${pi/2} 0 0"/>
        <geometry>
        	<mesh scale=" 0.001 0.001 0.001"  filename="file://$(find robot_models)/meshes/orpheus_x4/Wheel_v3_detailed.stl"/>
        </geometry>
        <material name="Black">
		<color rgba="0.15 0.15 0.15 1.0"/>
        </material>
      </visual>
      
      <collision>
        <origin xyz="0 0 0" rpy="${pi/2} 0 0"/>
        <geometry>
        	<cylinder radius="${wheel_radius}" length="${wheel_width}"/>
        </geometry>
      </collision>

  <xacro:cylinder_inertia m="0.5" r="${wheel_radius}" h="${wheel_width}"/>  
  </link>

	<gazebo reference="${prefix}_link">
		<mu1 value="1.0"/>
		<mu2 value="1.0"/>
		<kp value="10000000.0"/>
		<kd value="1.0"/>
		<fdir1 value=" 1 0 0"/>
	</gazebo>


    <joint name="${prefix}_joint" type="continuous">
      <parent link="base_link"/>
      <child link="${prefix}_link"/>
      <origin xyz="${x_reflect*wheel_xoff} ${y_reflect*(base_width/2+wheel_ygap)} ${-wheel_zoff}" rpy="0 0 0"/>
      <axis xyz="0 1 0"/>
    </joint>
    
    		<transmission name="${prefix}_trans" type="SimpleTransmission">
			<type>transmission_interface/SimpleTransmission</type>
			<actuator name="${prefix}_wheel_motor">
				<mechanicalReduction>1</mechanicalReduction>
			</actuator>
			<joint name="${prefix}_joint">
				<hardwareInterface>hardware_interface/VelocityJointInterface</hardwareInterface>
			</joint>
		</transmission>
    
    
  </xacro:macro>
  
  <!-- Nastaveni pozic jednotlivych kol -->
  <xacro:wheel prefix="drivewhl_rl" x_reflect="-1" y_reflect="1" />
  <xacro:wheel prefix="drivewhl_rr" x_reflect="-1" y_reflect="-1" />
  <xacro:wheel prefix="drivewhl_fl" x_reflect="1" y_reflect="1" />
  <xacro:wheel prefix="drivewhl_fr" x_reflect="1" y_reflect="-1" />

  <!-- Barvy v Gazebu -->
	<gazebo reference="base_link">
		<material>Gazebo/DarkGrey</material>
	</gazebo>
	<gazebo reference="mounting_plate_link">
		<material>Gazebo/White</material>
	</gazebo>
	<gazebo reference="drivewhl_fl_link">
		<material>Gazebo/DarkGrey</material>
	</gazebo>
	<gazebo reference="drivewhl_fr_link">
		<material>Gazebo/DarkGrey</material>
	</gazebo>
	<gazebo reference="drivewhl_rl_link">
		<material>Gazebo/DarkGrey</material>
	</gazebo>
	<gazebo reference="drivewhl_rr_link">
		<material>Gazebo/DarkGrey</material>
	</gazebo>
	
	
	<gazebo>
  	  <plugin name='diff_drive' filename='libgazebo_ros_diff_drive.so'>
    		<ros>
      			<namespace>/demo</namespace>
    		</ros>
	<!-- Pocet paru kol -->
    		<num_wheel_pairs>2</num_wheel_pairs>
    
	<!-- Kola -->
    		<left_joint>drivewhl_fl_joint</left_joint>
    		<right_joint>drivewhl_fr_joint</right_joint>
    		<left_joint>drivewhl_rl_joint</left_joint>
    		<right_joint>drivewhl_rr_joint</right_joint>
    

	<!-- kinematika -->
    		<wheel_separation>0.44</wheel_separation>
    		<wheel_diameter>0.4</wheel_diameter>


	<!-- limity -->
    		<max_wheel_torque>20</max_wheel_torque>
    		<max_wheel_acceleration>1.0</max_wheel_acceleration>

	<!-- vystup -->
    		<publish_odom>true</publish_odom>
    		<publish_odom_tf>true</publish_odom_tf>
    		<publish_wheel_tf>true</publish_wheel_tf>

    		<odometry_frame>odom</odometry_frame>
    		<robot_base_frame>base_link</robot_base_frame>
  	  </plugin>
	</gazebo>

  
</robot>
